<?xml version="1.0" ?>
<robot name="yellow" xmlns:xacro="http://ros.org/wiki/xacro">
  <xacro:property name="base_width" value="0.34"/>
  <xacro:property name="base_length" value="0.25"/>
  <xacro:property name="base_height" value="0.32"/>

  <xacro:property name="wheel_radius" value="0.0381"/>
  <xacro:property name="wheel_width" value="0.0254"/>
  <xacro:property name="wheel_ygap" value="-0.058"/>
  <xacro:property name="wheel_zoff" value="${base_height / 2}"/>
  <xacro:property name="wheel_xoff" value="0.05"/>

  <xacro:property name="caster_xoff" value="0.066"/>

  <!-- Define intertial property macros  -->
  <xacro:macro name="box_inertia" params="m w h d">
    <inertial>
      <origin xyz="0 0 0" rpy="${pi/2} 0 ${pi/2}"/>
      <mass value="${m}"/>
      <inertia ixx="${(m/12) * (h*h + d*d)}" ixy="0.0" ixz="0.0" iyy="${(m/12) * (w*w + d*d)}" iyz="0.0" izz="${(m/12) * (w*w + h*h)}"/>
    </inertial>
  </xacro:macro>

  <xacro:macro name="cylinder_inertia" params="m r h">
    <inertial>
      <origin xyz="0 0 0" rpy="${pi/2} 0 0" />
      <mass value="${m}"/>
      <inertia ixx="${(m/12) * (3*r*r + h*h)}" ixy = "0" ixz = "0" iyy="${(m/12) * (3*r*r + h*h)}" iyz = "0" izz="${(m/2) * (r*r)}"/>
    </inertial>
  </xacro:macro>

  <xacro:macro name="sphere_inertia" params="m r">
    <inertial>
      <mass value="${m}"/>
      <inertia ixx="${(2/5) * m * (r*r)}" ixy="0.0" ixz="0.0" iyy="${(2/5) * m * (r*r)}" iyz="0.0" izz="${(2/5) * m * (r*r)}"/>
    </inertial>
  </xacro:macro>

  <!-- Robot Base -->
  <gazebo reference="base_link">
    <visual>
      <material name="Eurobot/Yellow">
        <ambient>0.9686 0.7098 0.0 1.0</ambient>
        <diffuse>0.9686 0.7098 0.0 1.0</diffuse>
        <specular>0.9686 0.7098 0.0 1.0</specular>
      </material>
    </visual>
  </gazebo>
  <link name="base_link">
    <visual>
      <geometry>
        <box size="${base_length} ${base_width} ${base_height}"/>
      </geometry>
    </visual>
    <collision>
      <geometry>
        <box size="${base_length} ${base_width} ${base_height}"/>
      </geometry>
    </collision>
    <xacro:box_inertia m="15" w="${base_width}" d="${base_length}" h="${base_height}"/>
  </link>

  <joint name="base_joint" type="fixed">
    <parent link="base_link"/>
    <child link="base_footprint" />
    <origin xyz="0.0 0.0 ${-(wheel_radius+wheel_zoff)}" rpy="0 0 0"/>
  </joint>

  <!-- Robot Footprint -->
  <link name="base_footprint"/>

  <xacro:property name="catch_radius" value="0.150"/>

  <joint name="base_footprint__catch_footprint_joint" type="fixed">
    <parent link="base_footprint"/>
    <child link="catch_footprint_link" />
    <origin xyz="${base_length/2 + catch_radius} 0.0 0.01" rpy="0 0 0"/>
  </joint>

  <gazebo reference="catch_footprint_link">
    <visual>
      <material name="Eurobot/Yellow">
        <ambient>0.9686 0.7098 0.0 0.6</ambient>
        <diffuse>0.9686 0.7098 0.0 0.6</diffuse>
        <specular>0.9686 0.7098 0.0 0.6</specular>
      </material>
    </visual>
  </gazebo>
  <link name="catch_footprint_link">
  <visual>
    <origin xyz="0 0 0" rpy="0 0 0"/>
    <geometry>
      <cylinder length="0.04" radius="${catch_radius}"/>
    </geometry>
  </visual>
  </link>

  <!-- Wheels -->
  <xacro:macro name="wheel" params="prefix x_reflect y_reflect">
    <joint name="${prefix}_joint" type="continuous">
      <parent link="base_link"/>
      <child link="${prefix}_link"/>
      <origin xyz="${x_reflect*wheel_xoff} ${y_reflect*(base_width/2+wheel_ygap)} ${-wheel_zoff}" rpy="0 0 0"/>
      <axis xyz="0 1 0"/>
    </joint>

    <gazebo reference="${prefix}_link">
      <visual>
        <material name="Gray">
          <ambient>0.5 0.5 0.5 1.0</ambient>
          <diffuse>0.5 0.5 0.5 1.0</diffuse>
          <specular>0.5 0.5 0.5 1.0</specular>
        </material>
      </visual>
    </gazebo>
    <link name="${prefix}_link">
      <visual>
      <origin xyz="0 0 0" rpy="${pi/2} 0 0"/>
      <geometry>
        <cylinder length="${wheel_width}" radius="${wheel_radius}"/>
      </geometry>
    </visual>
    <collision>
      <origin xyz="0 0 0" rpy="${pi/2} 0 0"/>
      <geometry>
        <cylinder length="${wheel_width}" radius="${wheel_radius}"/>
      </geometry>
    </collision>
    <xacro:cylinder_inertia m="0.5" r="${wheel_radius}" h="${wheel_width}"/>
    </link>
  </xacro:macro>

  <xacro:wheel prefix="drivewhl_l" x_reflect="-1" y_reflect="1" />
  <xacro:wheel prefix="drivewhl_r" x_reflect="-1" y_reflect="-1" />

  <!-- Caster Wheel -->
  <joint name="caster_joint" type="fixed">
    <parent link="base_link"/>
    <child link="back_caster"/>
    <origin xyz="${caster_xoff} 0.0 ${-wheel_zoff}" rpy="0 0 0"/>
  </joint>

  <gazebo reference="back_caster">
    <visual>
      <material name="Gray">
      <ambient>0.5 0.5 0.5 1.0</ambient>
      <diffuse>0.5 0.5 0.5 1.0</diffuse>
      <specular>0.5 0.5 0.5 1.0</specular>
      </material>
    </visual>
    <mu1>0.0</mu1>
    <mu2>0.0</mu2>
  </gazebo>
  <link name="back_caster">
    <visual>
      <geometry>
        <sphere radius="${wheel_radius}"/>
      </geometry>
    </visual>
    <collision>
      <geometry>
        <sphere radius="${wheel_radius}"/>
      </geometry>
    </collision>
    <xacro:sphere_inertia m="1.0" r="${wheel_radius}"/>
  </link>

  <xacro:macro name="retach_column" params="id">
    <plugin filename="libignition-gazebo-retachable-joint-system.so" name="ignition::gazebo::systems::RetachableJoint">
      <parent_link>base_link</parent_link>
      <child_model>column_${id}</child_model>
      <child_link>body</child_link>
      <attach_topic>/yellow/column_${id}/attach</attach_topic>
      <detach_topic>/yellow/column_${id}/detach</detach_topic>
    </plugin>
  </xacro:macro>

  <xacro:macro name="retach_platform" params="id">
    <plugin filename="libignition-gazebo-retachable-joint-system.so" name="ignition::gazebo::systems::RetachableJoint">
      <parent_link>base_link</parent_link>
      <child_model>platform_${id}</child_model>
      <child_link>body</child_link>
      <attach_topic>/yellow/platform_${id}/attach</attach_topic>
      <detach_topic>/yellow/platform_${id}/detach</detach_topic>
    </plugin>
  </xacro:macro>

  <gazebo>
   <plugin
      filename="ignition-gazebo-diff-drive-system"
      name="gz::sim::systems::DiffDrive">
      <left_joint>drivewhl_l_joint</left_joint>
      <right_joint>drivewhl_r_joint</right_joint>
      <wheel_separation>${(base_width+2*wheel_ygap+wheel_width)}</wheel_separation>
      <wheel_radius>${wheel_radius}</wheel_radius>
      <max_linear_acceleration>1</max_linear_acceleration>
      <min_linear_acceleration>-1</min_linear_acceleration>
      <max_angular_acceleration>2</max_angular_acceleration>
      <min_angular_acceleration>-2</min_angular_acceleration>
      <max_linear_velocity>0.46</max_linear_velocity>
      <min_linear_velocity>-0.46</min_linear_velocity>
      <max_angular_velocity>1.9</max_angular_velocity>
      <min_angular_velocity>-1.9</min_angular_velocity>
      <topic>/yellow/cmd_vel</topic>
      <odom_topic>/yellow/odom</odom_topic>
      <tf_topic>tf</tf_topic>
      <frame_id>odom</frame_id>
      <child_frame_id>base_link</child_frame_id>
      <odom_publish_frequency>10</odom_publish_frequency>
    </plugin>
    <plugin
      filename="ignition-gazebo-pose-publisher-system"
      name="ignition::gazebo::systems::PosePublisher">
      <publish_nested_model_pose>true</publish_nested_model_pose>
      <use_pose_vector_msg>false</use_pose_vector_msg>
      <update_frequency>10</update_frequency>
    </plugin>
    
    <xacro:retach_column id="1" />
    <xacro:retach_column id="2" />
    <xacro:retach_column id="3" />
    <xacro:retach_column id="4" />
    <xacro:retach_column id="5" />
    <xacro:retach_column id="6" />
    <xacro:retach_column id="7" />
    <xacro:retach_column id="8" />
    <xacro:retach_column id="9" />
    <xacro:retach_column id="10" />
    <xacro:retach_column id="11" />
    <xacro:retach_column id="12" />
    <xacro:retach_column id="13" />
    <xacro:retach_column id="14" />
    <xacro:retach_column id="15" />
    <xacro:retach_column id="16" />
    <xacro:retach_column id="17" />
    <xacro:retach_column id="18" />
    <xacro:retach_column id="19" />
    <xacro:retach_column id="20" />
    <xacro:retach_column id="21" />
    <xacro:retach_column id="22" />
    <xacro:retach_column id="23" />
    <xacro:retach_column id="24" />
    <xacro:retach_column id="25" />
    <xacro:retach_column id="26" />
    <xacro:retach_column id="27" />
    <xacro:retach_column id="28" />
    <xacro:retach_column id="29" />
    <xacro:retach_column id="30" />
    <xacro:retach_column id="31" />
    <xacro:retach_column id="32" />
    <xacro:retach_column id="33" />
    <xacro:retach_column id="34" />
    <xacro:retach_column id="35" />
    <xacro:retach_column id="36" />
    <xacro:retach_column id="37" />
    <xacro:retach_column id="38" />
    <xacro:retach_column id="39" />
    <xacro:retach_column id="40" />

    <xacro:retach_platform id="1" />
    <xacro:retach_platform id="2" />
    <xacro:retach_platform id="3" />
    <xacro:retach_platform id="4" />
    <xacro:retach_platform id="5" />
    <xacro:retach_platform id="6" />
    <xacro:retach_platform id="7" />
    <xacro:retach_platform id="8" />
    <xacro:retach_platform id="9" />
    <xacro:retach_platform id="10" />
    <xacro:retach_platform id="11" />
    <xacro:retach_platform id="12" />
    <xacro:retach_platform id="13" />
    <xacro:retach_platform id="14" />
    <xacro:retach_platform id="15" />
    <xacro:retach_platform id="16" />
    <xacro:retach_platform id="17" />
    <xacro:retach_platform id="18" />
    <xacro:retach_platform id="19" />
    <xacro:retach_platform id="20" />
  </gazebo>

</robot>
